<?xml version="1.0"?>
<!-- Snakie demo arm (#311): a 3-DOF arm from URDF primitives — no external
     meshes, so it renders zero-setup in the Robot View. -->
<robot name="demo_arm">
  <link name="base">
    <visual>
      <geometry><cylinder radius="0.09" length="0.05"/></geometry>
      <material name="base_mat"><color rgba="0.30 0.34 0.40 1"/></material>
    </visual>
  </link>

  <joint name="shoulder" type="revolute">
    <parent link="base"/>
    <child link="upper_arm"/>
    <origin xyz="0 0 0.05" rpy="0 0 0"/>
    <axis xyz="0 0 1"/>
    <limit lower="-1.5708" upper="1.5708" effort="1" velocity="1"/>
  </joint>

  <link name="upper_arm">
    <visual>
      <origin xyz="0 0 0.16" rpy="0 0 0"/>
      <geometry><box size="0.055 0.055 0.30"/></geometry>
      <material name="arm_mat"><color rgba="0.90 0.62 0.22 1"/></material>
    </visual>
  </link>

  <joint name="elbow" type="revolute">
    <parent link="upper_arm"/>
    <child link="forearm"/>
    <origin xyz="0 0 0.31" rpy="0 0 0"/>
    <axis xyz="1 0 0"/>
    <limit lower="-2.2" upper="2.2" effort="1" velocity="1"/>
  </joint>

  <link name="forearm">
    <visual>
      <origin xyz="0 0 0.13" rpy="0 0 0"/>
      <geometry><box size="0.045 0.045 0.26"/></geometry>
      <material name="fore_mat"><color rgba="0.24 0.60 0.90 1"/></material>
    </visual>
  </link>

  <joint name="wrist" type="revolute">
    <parent link="forearm"/>
    <child link="gripper"/>
    <origin xyz="0 0 0.26" rpy="0 0 0"/>
    <axis xyz="1 0 0"/>
    <limit lower="-1.5708" upper="1.5708" effort="1" velocity="1"/>
  </joint>

  <link name="gripper">
    <visual>
      <origin xyz="0 0 0.03" rpy="0 0 0"/>
      <geometry><box size="0.09 0.025 0.06"/></geometry>
      <material name="grip_mat"><color rgba="0.85 0.86 0.90 1"/></material>
    </visual>
  </link>
</robot>
